## 高度な例外処理

{{ TOC }}

### 例外処理の場合分け

例外処理の文法は try except だけでなく、elseとfinallyがあります。
それぞれtryやexceptと同じような構文を持っており、その役割を簡単に説明すると以下のようになります。

*	else: 例外が発生しなかった場合のみ処理される
*	finally: 例外が発生してもしなくても処理される

正直なところ、else と finally の使いどころはあまり多くないのですが、
elseは例外が発生しなかった場合の処理に使い、finallyは必ず実施したい処理がある場合に使います。
使いどころがなかなか難しく、私は「あえてこの処理をします」という表明の目的以外では両者を使いません。

たとえば、オープンしたファイルをfinallyでクローズするということは言語を問わずよく実施されますが、
try/catchを抜けた箇所でのクローズでもだいたいカバーできます。
ただ、finallyにあえてクローズ処理を書くことで、「このtry/catchでファイルの資源を開放することを保証します」ということが、
ほかの人にも伝わるようになります。

else と finally がどのように動くかコードで確認してみます。
テスト用のコードは以前利用したものとほぼ同じですが、今回はelseとfinallyが追加されています。

```python
try:
  print('1: start of try')
  5 / 0
  print('2: end of try')

except Exception:
  print('3: error happens')

else:
  print("4: error doesn't happen")

finally:
  print('5: finally')
```

注目して欲しいのは、例外が発生したあとにどの処理が実行されているかということです。とりあえず実行してみます。

```
# python3 test.py
1: start of try
3: error happens
5: finally
```

例外が発生して、exceptの処理とfinallyの処理が実行されていることがわかります。
一方 else の処理は実行されていないことも分かります。
次に、例外を発生させなくした場合です。0による除算をコメントアウトします。

```python
try:
  print('1: start of try')
  # 5 / 0
  print('2: end of try')

except Exception:
  print('3: error happens')

else:
  print("4: error doesn't happen")

finally:
  print('5: finally')
```

これを実行すると以下のようになります。

```
# python3 test.py
1: start of try
2: end of try
4: error doesn't happen
5: finally
```

今度はexceptが呼ばれなくなり、代わりにelseが呼ばれています。
一方、finallyはまたもや呼ばれています。それほど複雑な動きではないと思うので、elseとfinallyの話はこのあたりで終わりとします 。

#### スタックトレース

try/exceptで例外をキャッチできることはわかりました。
ただ、やみくもに例外をキャッチするのは正直なところあまり行儀はよくないので、
「正しくエラーをキャッチ」してあげる必要があります。
たとえば、以下のコードがあるとしましょう。

```python
try:
    5/0
    a = [1,2,3]
    print(a[3])

except Exception:
    print('error happens')
```

このコードではいつものように5/0でエラーが起きますが、
それをコメントアウトしてもその後のリストの範囲外へのアクセスでエラーが発生します。
このコードには問題があるためエラーの発生自体は仕方がないのですが、このコードで問題となるのは以下の様な点です。

*	はたして0除算とリストの範囲外へのアクセスを同等に扱うべきか
*	そもそもこれは「例外処理」で対処するのではなくバグ修正すべき

今回のような短いコードであればすぐに問題は見つかるかもしれませんが、
実際にはもっと長く複雑なコードがひとつのtryのカバー範囲になります。
そのため「何が原因で、どこでどのようなエラーが発生したのか」を正確に把握することは難しいです。
単にtry/catchを使うだけでなく、エラーの原因を把握できれば、「何を修正すべき」か、
「どのような例外クラスを使うべきか」がよくわかります。

実はこの原因と問題の把握は、try/catchを利用していなければできていました。
たとえば上記コードのtry/catchを外して実行すると、5/0を実行した際に処理の中断とともに、
以下のようなエラー出力が得られてどこで何が発生していたのか一目でわかります。

```
$ python3 test.py
Traceback (most recent call last):
  File "test.py", line 1, in <module>
    5/0
ZeroDivisionError: division by zero
```

また、a[3]での範囲外のアクセスも以下のようにエラー原因が一目瞭然でわかります。

```
$ python3 test.py
Traceback (most recent call last):
  File "test.py", line 2, in <module>
    a[3]
IndexError: list index out of range
```

こういったエラー出力はスタックトレース(stack trace)と呼ばれていて、コードのどこでどういうふうに失敗したかを詳細に出力してくれます。もう少し詳細なトレースを見てみます。
以下のようなコードがあるとしましょう。分かりやすいように行数付きで書いています。

```
 1    class A:
 2      def test(self, b):
 3        return b.div(0)
 4
 5    class B:
 6      def div(self, value):
 7        return 5/value
 8
 9    a = A()
10    b = B()
11    value = a.test(b)
```

このコードを実行すると最終的に 0 による割り算が発生してエラーとなってしまいます。実行すると以下のようなエラー出力が得られました。

```
$ python3 test.py
Traceback (most recent call last):
  File "test.py", line 11, in <module>
    value = a.test(b)
  File "test.py", line 3, in test
    return b.div(0)
  File "test.py", line 7, in div
    return 5/value
ZeroDivisionError: division by zero
```

このエラーを上から読むと 11 行目で “value = a.test(b)” を実行し、3行目で” return b.div(0)” を実行し、
7 行目で “return 5/value” を実行し、そこで ZeroDivisionError となったことが分かります。

### traceback モジュール

先ほど説明した「エラーを変数に格納し出力する」ことである程度の詳細を得ることは可能です。
ただ、より詳細を把握したい場合は traceback モジュールを使ってプログラムを停止することなくスタックトレースを取得すると便利です。
サンプルコードを以下に記載します。

```python
import traceback

print(1)
try:
  print(2)
  5/0
  print(3)
except Exception:
  print(4)
  # 文字列で取得
  text = traceback.format_exc()
  print(text)
  # ファイルに書き込み
  f = open('error.log', 'a')
  traceback.print_exc(file=f)
print(5)
```

上記では traceback モジュールの関数を2つ使っています。
ひとつめの format_exc() 関数はスタックトレースを文字列として返し、
2つめのprint_exc() は渡されたファイルオブジェクトにスタックトレースを書き込みます。
上記の実行結果は以下となります。

```
$ python3 test.py
1
2
4
Traceback (most recent call last):
  File "test.py", line 6, in <module>
    5/0
ZeroDivisionError: division by zero

5
```

また上記スタックトレースと同じ内容が書かれたファイルも作成されています。
プログラムの標準出力ではなくログファイルに出力する際にはこの機能を使うか、
もしくは logging モジュールを使ってエラーの文字列をファイルに書くのがよいと思います。

### キャッチした例外の丸投げ

先に説明したraiseなのですが、もうひとつ別の使い方があります。
それは「exceptの中で呼び出すことで、エラーを呼び出し元で処理してもらう」というものです。
以下のコードを見てください。

```python
def fun1():
  try:
    raise Exception('error in fun1()')
  except:
    print("1: fun1 can't handle this error")
    # 同じエラーを投げる
    raise

def fun2():
  try:
    print('2: call fun1')
    fun1()
    print('3: done')
  except Exception as e:
    print('4: catch error which happens in fun1()')
    print(e)

fun2()
```

関数fun2()はfun1() をその内部で呼び出しています。
fun1() 内部でエラーを発生させて自ら except でそれを受け取っていますが、そのexceptの中でraiseをしています。
こうすると同じエラーが再発生するので、実質的に「呼び出し元に処理を依頼する」ことになります。
一応try/exceptでエラーをハンドルしようとしたけれども「ここでは対処しきれないエラーなので、
呼び出し元で例外処理をしてもらう」というような場合で同じエラーを再度 raise します。

これを実行すると以下のような出力になります。

```
$ python3 test.py
2: call fun1
1: fun1 can't handle this error
4: catch error which happens in fun1()
error in fun1()
```

fun1() の中で再度 raise されたエラーを fun2() が受け取っているので、
例外のメッセージがオリジナルのもののままになっています。
なお、例外を処理しきれない場合は raise で同じものを再度発生させるのではなく別のエラーを raise させても構いません。
例えば適切なエラーメッセージに更新して再度 raise するというのはいいアイデアかもしれません。
